Workbook
Name Slicer_channel: #N/A
Name Slicer_month: #N/A

Sheet retail_campaigns
A1: campaign_id | B1: name | C1: start_date | D1: end_date | E1: budget
A2: MKT-01 | B2: Summer Sale | C2: 45078 | D2: 45107 | E2: 5000
A3: MKT-02 | B3: Black Friday | C3: 45250 | D3: 45260 | E3: 12000
A4: MKT-03 | B4: Holiday Cheer | C4: 45275 | D4: 45291 | E4: 8000
A5: MKT-04 | B5: New Year Refresh | C5: 45292 | D5: 45306 | E5: 4000

Sheet retail_products
A1: product_id | B1: product_name | C1: category | D1: unit_cost | E1: unit_price | F1: stock_level
A2: P-2001 | B2: Home Decor Item 1 | C2: Home Decor | D2: 438.33 | E2: 1011.63 | F2: 184
A3: P-2002 | B3: Apparel Item 2 | C3: Apparel | D3: 218.74 | E3: 295.45 | F3: 435
A4: P-2003 | B4: Electronics Item 3 | C4: Electronics | D4: 14.74 | E4: 20.34 | F4: 331
A5: P-2004 | B5: Home Decor Item 4 | C5: Home Decor | D5: 171.04 | E5: 404.15 | F5: 489
A6: P-2005 | B6: Sports Item 5 | C6: Sports | D6: 141.47 | E6: 304.58 | F6: 190
A7: P-2006 | B7: Apparel Item 6 | C7: Apparel | D7: 99.61 | E7: 171.43 | F7: 492
A8: P-2007 | B8: Beauty Item 7 | C8: Beauty | D8: 143.2 | E8: 243.64 | F8: 435
A9: P-2008 | B9: Beauty Item 8 | C9: Beauty | D9: 401.95 | E9: 821.38 | F9: 408
A10: P-2009 | B10: Home Decor Item 9 | C10: Home Decor | D10: 65.4 | E10: 137.67 | F10: 30
A11: P-2010 | B11: Home Decor Item 10 | C11: Home Decor | D11: 60.82 | E11: 145.03 | F11: 247
A12: P-2011 | B12: Sports Item 11 | C12: Sports | D12: 342.41 | E12: 491.58 | F12: 194
A13: P-2012 | B13: Apparel Item 12 | C13: Apparel | D13: 309.57 | E13: 718.62 | F13: 450
... A51: P-2050 | B51: Apparel Item 50 | C51: Apparel | D51: 231.89 | E51: 318.47 | F51: 211

Sheet retail_customers
A1: customer_id | B1: age | C1: gender | D1: region | E1: segment | F1: signup_date
A2: CUST-1000 | B2: 58 | C2: Male | D2: North | E2: Bronze | F2: 44478
A3: CUST-1001 | B3: 33 | C3: Male | D3: South | E3: Bronze | F3: 44301
A4: CUST-1002 | B4: 61 | C4: Other | D4: North | E4: Bronze | F4: 44629
A5: CUST-1003 | B5: 20 | C5: Male | D5: North | E5: Gold | F5: 44435
A6: CUST-1004 | B6: 50 | C6: Other | D6: North | E6: Bronze | F6: 44400
A7: CUST-1005 | B7: 63 | C7: Other | D7: West | E7: Gold | F7: 44656
A8: CUST-1006 | B8: 55 | C8: Female | D8: North | E8: Gold | F8: 44911
A9: CUST-1007 | B9: 45 | C9: Female | D9: East | E9: Gold | F9: 44417
A10: CUST-1008 | B10: 66 | C10: Female | D10: North | E10: Gold | F10: 44586
A11: CUST-1009 | B11: 24 | C11: Female | D11: East | E11: Bronze | F11: 44467
A12: CUST-1010 | B12: 69 | C12: Male | D12: West | E12: Bronze | F12: 44324
A13: CUST-1011 | B13: 42 | C13: Male | D13: East | E13: Bronze | F13: 44830
... A1001: CUST-1999 | B1001: 36 | C1001: Female | D1001: West | E1001: Gold | F1001: 44299

Sheet retail_sales
A1: order_id | B1: order_date | C1: customer_id | D1: product_id | E1: quantity | F1: quantity edited | G1: channel | H1: discount_applied | I1: unit_price | J1: unit_cost | K1: gross_revenue | L1: discount_amount | M1: net_revenue | N1: profit | O1: month
A2: ORD-50001 | B2: 45235 | C2: CUST-1716 | D2: P-2048 | E2: 5 | F2: =IF(E2<0,0,E2) -> 5 | G2: Mobile App | H2: 0.17 | I2: =_xlfn.XLOOKUP(D2, 'retail_products'!$A:$A, 'retail_products'!$E:$E, "") -> 436.93 | J2: =_xlfn.XLOOKUP(D2, 'retail_products'!$A:$A, 'retail_products'!$D:$D, "") -> 257.01 | K2: =E2*I2 -> 2184.65 | L2: =K2*H2 -> 371.3905 | M2: =K2-L2 -> 1813.2595 | N2: =M2-(E2*J2) -> 528.2095 | O2: =TEXT(B2,"mmm") -> Nov
A3: ORD-50002 | B3: 45038 | C3: CUST-1205 | D3: P-2014 | E3: 5 | F3: =IF(E3<0,0,E3) -> 5 | G3: Online | H3: 0.2 | I3: =_xlfn.XLOOKUP(D3, 'retail_products'!$A:$A, 'retail_products'!$E:$E, "") -> 289.73 | J3: =_xlfn.XLOOKUP(D3, 'retail_products'!$A:$A, 'retail_products'!$D:$D, "") -> 225.94 | K3: =E3*I3 -> 1448.65 | L3: =K3*H3 -> 289.73 | M3: =K3-L3 -> 1158.92 | N3: =M3-(E3*J3) -> 29.22 | O3: =TEXT(B3,"mmm") -> Apr
A4: ORD-50003 | B4: 45018 | C4: CUST-1515 | D4: P-2035 | E4: 3 | F4: =IF(E4<0,0,E4) -> 3 | G4: Mobile App | H4: 0 | I4: =_xlfn.XLOOKUP(D4, 'retail_products'!$A:$A, 'retail_products'!$E:$E, "") -> 403.95 | J4: =_xlfn.XLOOKUP(D4, 'retail_products'!$A:$A, 'retail_products'!$D:$D, "") -> 177.26 | K4: =E4*I4 -> 1211.85 | L4: =K4*H4 -> 0 | M4: =K4-L4 -> 1211.85 | N4: =M4-(E4*J4) -> 680.07 | O4: =TEXT(B4,"mmm") -> Apr
A5: ORD-50004 | B5: 45268 | C5: CUST-1727 | D5: P-2027 | E5: 5 | F5: =IF(E5<0,0,E5) -> 5 | G5: Mobile App | H5: 0 | I5: =_xlfn.XLOOKUP(D5, 'retail_products'!$A:$A, 'retail_products'!$E:$E, "") -> 458.87 | J5: =_xlfn.XLOOKUP(D5, 'retail_products'!$A:$A, 'retail_products'!$D:$D, "") -> 375.17 | K5: =E5*I5 -> 2294.35 | L5: =K5*H5 -> 0 | M5: =K5-L5 -> 2294.35 | N5: =M5-(E5*J5) -> 418.5 | O5: =TEXT(B5,"mmm") -> Dec
A6: ORD-50005 | B6: 45122 | C6: CUST-1148 | D6: P-2004 | E6: 1 | F6: =IF(E6<0,0,E6) -> 1 | G6: In-Store | H6: 0 | I6: =_xlfn.XLOOKUP(D6, 'retail_products'!$A:$A, 'retail_products'!$E:$E, "") -> 404.15 | J6: =_xlfn.XLOOKUP(D6, 'retail_products'!$A:$A, 'retail_products'!$D:$D, "") -> 171.04 | K6: =E6*I6 -> 404.15 | L6: =K6*H6 -> 0 | M6: =K6-L6 -> 404.15 | N6: =M6-(E6*J6) -> 233.11 | O6: =TEXT(B6,"mmm") -> Jul
A7: ORD-50006 | B7: 45001 | C7: CUST-1859 | D7: P-2004 | E7: 3 | F7: =IF(E7<0,0,E7) -> 3 | G7: In-Store | H7: 0 | I7: =_xlfn.XLOOKUP(D7, 'retail_products'!$A:$A, 'retail_products'!$E:$E, "") -> 404.15 | J7: =_xlfn.XLOOKUP(D7, 'retail_products'!$A:$A, 'retail_products'!$D:$D, "") -> 171.04 | K7: =E7*I7 -> 1212.45 | L7: =K7*H7 -> 0 | M7: =K7-L7 -> 1212.45 | N7: =M7-(E7*J7) -> 699.33 | O7: =TEXT(B7,"mmm") -> Mar
A8: ORD-50007 | B8: 45371 | C8: CUST-1691 | D8: P-2048 | E8: 5 | F8: =IF(E8<0,0,E8) -> 5 | G8: Online | H8: 0 | I8: =_xlfn.XLOOKUP(D8, 'retail_products'!$A:$A, 'retail_products'!$E:$E, "") -> 436.93 | J8: =_xlfn.XLOOKUP(D8, 'retail_products'!$A:$A, 'retail_products'!$D:$D, "") -> 257.01 | K8: =E8*I8 -> 2184.65 | L8: =K8*H8 -> 0 | M8: =K8-L8 -> 2184.65 | N8: =M8-(E8*J8) -> 899.6 | O8: =TEXT(B8,"mmm") -> Mar
A9: ORD-50008 | B9: 45334 | C9: CUST-1817 | D9: P-2045 | E9: 3 | F9: =IF(E9<0,0,E9) -> 3 | G9: In-Store | H9: 0.29 | I9: =_xlfn.XLOOKUP(D9, 'retail_products'!$A:$A, 'retail_products'!$E:$E, "") -> 769.55 | J9: =_xlfn.XLOOKUP(D9, 'retail_products'!$A:$A, 'retail_products'!$D:$D, "") -> 421.02 | K9: =E9*I9 -> 2308.65 | L9: =K9*H9 -> 669.5085 | M9: =K9-L9 -> 1639.1415 | N9: =M9-(E9*J9) -> 376.0815 | O9: =TEXT(B9,"mmm") -> Feb
B10: 45087 | C10: CUST-1989 | D10: P-2036 | E10: 1 | F10: =IF(E10<0,0,E10) -> 1 | G10: In-Store | H10: 0.27 | I10: =_xlfn.XLOOKUP(D10, 'retail_products'!$A:$A, 'retail_products'!$E:$E, "") -> 469.35 | J10: =_xlfn.XLOOKUP(D10, 'retail_products'!$A:$A, 'retail_products'!$D:$D, "") -> 278.37 | K10: =E10*I10 -> 469.35 | L10: =K10*H10 -> 126.7245 | M10: =K10-L10 -> 342.6255 | N10: =M10-(E10*J10) -> 64.2555 | O10: =TEXT(B10,"mmm") -> Jun
A11: ORD-50010 | B11: 45287 | C11: CUST-1726 | D11: P-2042 | E11: 3 | F11: =IF(E11<0,0,E11) -> 3 | G11: Mobile App | H11: 0.09 | I11: =_xlfn.XLOOKUP(D11, 'retail_products'!$A:$A, 'retail_products'!$E:$E, "") -> 693.46 | J11: =_xlfn.XLOOKUP(D11, 'retail_products'!$A:$A, 'retail_products'!$D:$D, "") -> 388.35 | K11: =E11*I11 -> 2080.38 | L11: =K11*H11 -> 187.2342 | M11: =K11-L11 -> 1893.1458 | N11: =M11-(E11*J11) -> 728.0958 | O11: =TEXT(B11,"mmm") -> Dec
A12: ORD-50011 | B12: 45017 | C12: CUST-1699 | D12: P-2005 | E12: 2 | F12: =IF(E12<0,0,E12) -> 2 | G12: Online | H12: 0 | I12: =_xlfn.XLOOKUP(D12, 'retail_products'!$A:$A, 'retail_products'!$E:$E, "") -> 304.58 | J12: =_xlfn.XLOOKUP(D12, 'retail_products'!$A:$A, 'retail_products'!$D:$D, "") -> 141.47 | K12: =E12*I12 -> 609.16 | L12: =K12*H12 -> 0 | M12: =K12-L12 -> 609.16 | N12: =M12-(E12*J12) -> 326.22 | O12: =TEXT(B12,"mmm") -> Apr
A13: ORD-50012 | B13: 45211 | C13: CUST-1270 | D13: P-2009 | E13: 2 | F13: =IF(E13<0,0,E13) -> 2 | G13: Mobile App | H13: 0.01 | I13: =_xlfn.XLOOKUP(D13, 'retail_products'!$A:$A, 'retail_products'!$E:$E, "") -> 137.67 | J13: =_xlfn.XLOOKUP(D13, 'retail_products'!$A:$A, 'retail_products'!$D:$D, "") -> 65.4 | K13: =E13*I13 -> 275.34 | L13: =K13*H13 -> 2.7534 | M13: =K13-L13 -> 272.5866 | N13: =M13-(E13*J13) -> 141.7866 | O13: =TEXT(B13,"mmm") -> Oct
A14: ORD-50013 | B14: 45092 | C14: CUST-1611 | D14: P-2004 | E14: 5 | F14: =IF(E14<0,0,E14) -> 5 | G14: Mobile App | H14: 0 | I14: =_xlfn.XLOOKUP(D14, 'retail_products'!$A:$A, 'retail_products'!$E:$E, "") -> 404.15 | J14: =_xlfn.XLOOKUP(D14, 'retail_products'!$A:$A, 'retail_products'!$D:$D, "") -> 171.04 | K14: =E14*I14 -> 2020.75 | L14: =K14*H14 -> 0 | M14: =K14-L14 -> 2020.75 | N14: =M14-(E14*J14) -> 1165.55 | O14: =TEXT(B14,"mmm") -> Jun
A15: ORD-50014 | B15: 45328 | C15: CUST-1724 | D15: P-2021 | E15: 5 | F15: =IF(E15<0,0,E15) -> 5 | G15: Mobile App | H15: 0 | I15: =_xlfn.XLOOKUP(D15, 'retail_products'!$A:$A, 'retail_products'!$E:$E, "") -> 466.51 | J15: =_xlfn.XLOOKUP(D15, 'retail_products'!$A:$A, 'retail_products'!$D:$D, "") -> 257.73 | K15: =E15*I15 -> 2332.55 | L15: =K15*H15 -> 0 | M15: =K15-L15 -> 2332.55 | N15: =M15-(E15*J15) -> 1043.9 | O15: =TEXT(B15,"mmm") -> Feb
A16: ORD-50015 | B16: 45205 | C16: CUST-1549 | D16: P-2026 | E16: 1 | F16: =IF(E16<0,0,E16) -> 1 | G16: In-Store | H16: 0 | I16: =_xlfn.XLOOKUP(D16, 'retail_products'!$A:$A, 'retail_products'!$E:$E, "") -> 765.43 | J16: =_xlfn.XLOOKUP(D16, 'retail_products'!$A:$A, 'retail_products'!$D:$D, "") -> 429.73 | K16: =E16*I16 -> 765.43 | L16: =K16*H16 -> 0 | M16: =K16-L16 -> 765.43 | N16: =M16-(E16*J16) -> 335.7 | O16: =TEXT(B16,"mmm") -> Oct
A17: ORD-50016 | B17: 45038 | C17: CUST-1973 | D17: P-2049 | E17: 5 | F17: =IF(E17<0,0,E17) -> 5 | G17: Mobile App | H17: 0 | I17: =_xlfn.XLOOKUP(D17, 'retail_products'!$A:$A, 'retail_products'!$E:$E, "") -> 353.33 | J17: =_xlfn.XLOOKUP(D17, 'retail_products'!$A:$A, 'retail_products'!$D:$D, "") -> 144.06 | K17: =E17*I17 -> 1766.65 | L17: =K17*H17 -> 0 | M17: =K17-L17 -> 1766.65 | N17: =M17-(E17*J17) -> 1046.35 | O17: =TEXT(B17,"mmm") -> Apr
A18: ORD-50017 | B18: 45269 | C18: CUST-1354 | D18: P-2029 | E18: 2 | F18: =IF(E18<0,0,E18) -> 2 | G18: Online | H18: 0 | I18: =_xlfn.XLOOKUP(D18, 'retail_products'!$A:$A, 'retail_products'!$E:$E, "") -> 975.87 | J18: =_xlfn.XLOOKUP(D18, 'retail_products'!$A:$A, 'retail_products'!$D:$D, "") -> 397.97 | K18: =E18*I18 -> 1951.74 | L18: =K18*H18 -> 0 | M18: =K18-L18 -> 1951.74 | N18: =M18-(E18*J18) -> 1155.8 | O18: =TEXT(B18,"mmm") -> Dec
A19: ORD-50018 | B19: 45091 | C19: CUST-1390 | D19: P-2008 | E19: 4 | F19: =IF(E19<0,0,E19) -> 4 | G19: Mobile App | H19: 0.11 | I19: =_xlfn.XLOOKUP(D19, 'retail_products'!$A:$A, 'retail_products'!$E:$E, "") -> 821.38 | J19: =_xlfn.XLOOKUP(D19, 'retail_products'!$A:$A, 'retail_products'!$D:$D, "") -> 401.95 | K19: =E19*I19 -> 3285.52 | L19: =K19*H19 -> 361.4072 | M19: =K19-L19 -> 2924.1128 | N19: =M19-(E19*J19) -> 1316.3128 | O19: =TEXT(B19,"mmm") -> Jun
A20: ORD-50019 | B20: 45338 | C20: CUST-1520 | D20: P-2029 | E20: 4 | F20: =IF(E20<0,0,E20) -> 4 | G20: Mobile App | H20: 0 | I20: =_xlfn.XLOOKUP(D20, 'retail_products'!$A:$A, 'retail_products'!$E:$E, "") -> 975.87 | J20: =_xlfn.XLOOKUP(D20, 'retail_products'!$A:$A, 'retail_products'!$D:$D, "") -> 397.97 | K20: =E20*I20 -> 3903.48 | L20: =K20*H20 -> 0 | M20: =K20-L20 -> 3903.48 | N20: =M20-(E20*J20) -> 2311.6 | O20: =TEXT(B20,"mmm") -> Feb
A21: ORD-50020 | B21: 44976 | C21: CUST-1171 | D21: P-2050 | E21: 5 | F21: =IF(E21<0,0,E21) -> 5 | G21: Mobile App | H21: 0.26 | I21: =_xlfn.XLOOKUP(D21, 'retail_products'!$A:$A, 'retail_products'!$E:$E, "") -> 318.47 | J21: =_xlfn.XLOOKUP(D21, 'retail_products'!$A:$A, 'retail_products'!$D:$D, "") -> 231.89 | K21: =E21*I21 -> 1592.35 | L21: =K21*H21 -> 414.011 | M21: =K21-L21 -> 1178.339 | N21: =M21-(E21*J21) -> 18.889 | O21: =TEXT(B21,"mmm") -> Feb
A22: ORD-50021 | B22: 45144 | C22: CUST-1855 | D22: P-2007 | E22: 2 | F22: =IF(E22<0,0,E22) -> 2 | G22: In-Store | H22: 0 | I22: =_xlfn.XLOOKUP(D22, 'retail_products'!$A:$A, 'retail_products'!$E:$E, "") -> 243.64 | J22: =_xlfn.XLOOKUP(D22, 'retail_products'!$A:$A, 'retail_products'!$D:$D, "") -> 143.2 | K22: =E22*I22 -> 487.28 | L22: =K22*H22 -> 0 | M22: =K22-L22 -> 487.28 | N22: =M22-(E22*J22) -> 200.88 | O22: =TEXT(B22,"mmm") -> Aug
... A28: ORD-50027 | B28: 45007 | C28: CUST-1546 | D28: P-2015 | E28: 2 | F28: =IF(E28<0,0,E28) -> 2 | G28: In-Store | H28: 0.04 | I28: =_xlfn.XLOOKUP(D28, 'retail_products'!$A:$A, 'retail_products'!$E:$E, "") -> 37.4 | J28: =_xlfn.XLOOKUP(D28, 'retail_products'!$A:$A, 'retail_products'!$D:$D, "") -> 16.06 | K28: =E28*I28 -> 74.8 | L28: =K28*H28 -> 2.992 | M28: =K28-L28 -> 71.808 | N28: =M28-(E28*J28) -> 39.688 | O28: =TEXT(B28,"mmm") -> Mar
A29: ORD-50028 | B29: 12/13/23 | C29: CUST-1908 | D29: P-2047 | E29: 3 | F29: =IF(E29<0,0,E29) -> 3 | G29: Online | H29: 0 | I29: =_xlfn.XLOOKUP(D29, 'retail_products'!$A:$A, 'retail_products'!$E:$E, "") -> 124.81 | J29: =_xlfn.XLOOKUP(D29, 'retail_products'!$A:$A, 'retail_products'!$D:$D, "") -> 60.74 | K29: =E29*I29 -> 374.43 | L29: =K29*H29 -> 0 | M29: =K29-L29 -> 374.43 | N29: =M29-(E29*J29) -> 192.21 | O29: =TEXT(B29,"mmm") -> 12/13/23
A30: ORD-50029 | B30: 44929 | C30: CUST-1586 | D30: P-2039 | E30: 4 | F30: =IF(E30<0,0,E30) -> 4 | G30: Mobile App | H30: 0.22 | I30: =_xlfn.XLOOKUP(D30, 'retail_products'!$A:$A, 'retail_products'!$E:$E, "") -> 796.89 | J30: =_xlfn.XLOOKUP(D30, 'retail_products'!$A:$A, 'retail_products'!$D:$D, "") -> 465.81 | K30: =E30*I30 -> 3187.56 | L30: =K30*H30 -> 701.2632 | M30: =K30-L30 -> 2486.2968 | N30: =M30-(E30*J30) -> 623.0568 | O30: =TEXT(B30,"mmm") -> Jan
A31: ORD-50030 | B31: 45035 | C31: CUST-1422 | D31: P-2042 | E31: 5 | F31: =IF(E31<0,0,E31) -> 5 | G31: In-Store | H31: 0 | I31: =_xlfn.XLOOKUP(D31, 'retail_products'!$A:$A, 'retail_products'!$E:$E, "") -> 693.46 | J31: =_xlfn.XLOOKUP(D31, 'retail_products'!$A:$A, 'retail_products'!$D:$D, "") -> 388.35 | K31: =E31*I31 -> 3467.3 | L31: =K31*H31 -> 0 | M31: =K31-L31 -> 3467.3 | N31: =M31-(E31*J31) -> 1525.55 | O31: =TEXT(B31,"mmm") -> Apr
A32: ORD-50031 | B32: 45019 | C32: CUST-1687 | D32: P-2037 | E32: 1 | F32: =IF(E32<0,0,E32) -> 1 | G32: In-Store | H32: 0 | I32: =_xlfn.XLOOKUP(D32, 'retail_products'!$A:$A, 'retail_products'!$E:$E, "") -> 827.09 | J32: =_xlfn.XLOOKUP(D32, 'retail_products'!$A:$A, 'retail_products'!$D:$D, "") -> 449.47 | K32: =E32*I32 -> 827.09 | L32: =K32*H32 -> 0 | M32: =K32-L32 -> 827.09 | N32: =M32-(E32*J32) -> 377.62 | O32: =TEXT(B32,"mmm") -> Apr
A33: ORD-50032 | B33: 44964 | C33: CUST-1297 | D33: P-2043 | E33: 1 | F33: =IF(E33<0,0,E33) -> 1 | G33: In-Store | H33: 0 | I33: =_xlfn.XLOOKUP(D33, 'retail_products'!$A:$A, 'retail_products'!$E:$E, "") -> 657.99 | J33: =_xlfn.XLOOKUP(D33, 'retail_products'!$A:$A, 'retail_products'!$D:$D, "") -> 478.53 | K33: =E33*I33 -> 657.99 | L33: =K33*H33 -> 0 | M33: =K33-L33 -> 657.99 | N33: =M33-(E33*J33) -> 179.46 | O33: =TEXT(B33,"mmm") -> Feb
A34: ORD-50033 | B34: 45270 | C34: CUST-1671 | D34: P-2016 | E34: 1 | F34: =IF(E34<0,0,E34) -> 1 | G34: In-Store | H34: 0 | I34: =_xlfn.XLOOKUP(D34, 'retail_products'!$A:$A, 'retail_products'!$E:$E, "") -> 543.76 | J34: =_xlfn.XLOOKUP(D34, 'retail_products'!$A:$A, 'retail_products'!$D:$D, "") -> 364.65 | K34: =E34*I34 -> 543.76 | L34: =K34*H34 -> 0 | M34: =K34-L34 -> 543.76 | N34: =M34-(E34*J34) -> 179.11 | O34: =TEXT(B34,"mmm") -> Dec
A35: ORD-50034 | B35: 45242 | C35: CUST-1675 | D35: P-2020 | E35: 5 | F35: =IF(E35<0,0,E35) -> 5 | G35: In-Store | H35: 0 | I35: =_xlfn.XLOOKUP(D35, 'retail_products'!$A:$A, 'retail_products'!$E:$E, "") -> 892.78 | J35: =_xlfn.XLOOKUP(D35, 'retail_products'!$A:$A, 'retail_products'!$D:$D, "") -> 447.11 | K35: =E35*I35 -> 4463.9 | L35: =K35*H35 -> 0 | M35: =K35-L35 -> 4463.9 | N35: =M35-(E35*J35) -> 2228.35 | O35: =TEXT(B35,"mmm") -> Nov
A36: ORD-50035 | B36: 45087 | C36: CUST-1252 | D36: P-2015 | E36: 4 | F36: =IF(E36<0,0,E36) -> 4 | G36: In-Store | H36: 0.14 | I36: =_xlfn.XLOOKUP(D36, 'retail_products'!$A:$A, 'retail_products'!$E:$E, "") -> 37.4 | J36: =_xlfn.XLOOKUP(D36, 'retail_products'!$A:$A, 'retail_products'!$D:$D, "") -> 16.06 | K36: =E36*I36 -> 149.6 | L36: =K36*H36 -> 20.944 | M36: =K36-L36 -> 128.656 | N36: =M36-(E36*J36) -> 64.416 | O36: =TEXT(B36,"mmm") -> Jun
A37: ORD-50036 | B37: 45110 | C37: CUST-1793 | D37: P-2020 | E37: 4 | F37: =IF(E37<0,0,E37) -> 4 | G37: In-Store | H37: 0.04 | I37: =_xlfn.XLOOKUP(D37, 'retail_products'!$A:$A, 'retail_products'!$E:$E, "") -> 892.78 | J37: =_xlfn.XLOOKUP(D37, 'retail_products'!$A:$A, 'retail_products'!$D:$D, "") -> 447.11 | K37: =E37*I37 -> 3571.12 | L37: =K37*H37 -> 142.8448 | M37: =K37-L37 -> 3428.2752 | N37: =M37-(E37*J37) -> 1639.8352 | O37: =TEXT(B37,"mmm") -> Jul
A38: ORD-50037 | B38: 45202 | C38: CUST-1201 | D38: P-2017 | E38: 1 | F38: =IF(E38<0,0,E38) -> 1 | G38: Mobile App | H38: 0 | I38: =_xlfn.XLOOKUP(D38, 'retail_products'!$A:$A, 'retail_products'!$E:$E, "") -> 553.76 | J38: =_xlfn.XLOOKUP(D38, 'retail_products'!$A:$A, 'retail_products'!$D:$D, "") -> 264.36 | K38: =E38*I38 -> 553.76 | L38: =K38*H38 -> 0 | M38: =K38-L38 -> 553.76 | N38: =M38-(E38*J38) -> 289.4 | O38: =TEXT(B38,"mmm") -> Oct
A39: ORD-50038 | B39: 45224 | C39: CUST-1592 | D39: P-2026 | E39: 5 | F39: =IF(E39<0,0,E39) -> 5 | G39: Mobile App | H39: 0 | I39: =_xlfn.XLOOKUP(D39, 'retail_products'!$A:$A, 'retail_products'!$E:$E, "") -> 765.43 | J39: =_xlfn.XLOOKUP(D39, 'retail_products'!$A:$A, 'retail_products'!$D:$D, "") -> 429.73 | K39: =E39*I39 -> 3827.15 | L39: =K39*H39 -> 0 | M39: =K39-L39 -> 3827.15 | N39: =M39-(E39*J39) -> 1678.5 | O39: =TEXT(B39,"mmm") -> Oct
A40: ORD-50039 | B40: 45323 | C40: CUST-1152 | D40: P-2024 | E40: 4 | F40: =IF(E40<0,0,E40) -> 4 | G40: In-Store | H40: 0 | I40: =_xlfn.XLOOKUP(D40, 'retail_products'!$A:$A, 'retail_products'!$E:$E, "") -> 560.78 | J40: =_xlfn.XLOOKUP(D40, 'retail_products'!$A:$A, 'retail_products'!$D:$D, "") -> 325.23 | K40: =E40*I40 -> 2243.12 | L40: =K40*H40 -> 0 | M40: =K40-L40 -> 2243.12 | N40: =M40-(E40*J40) -> 942.2 | O40: =TEXT(B40,"mmm") -> Feb
A41: ORD-50040 | B41: 09/14/23 | C41: CUST-1522 | D41: P-2006 | E41: 4 | F41: =IF(E41<0,0,E41) -> 4 | G41: Mobile App | H41: 0 | I41: =_xlfn.XLOOKUP(D41, 'retail_products'!$A:$A, 'retail_products'!$E:$E, "") -> 171.43 | J41: =_xlfn.XLOOKUP(D41, 'retail_products'!$A:$A, 'retail_products'!$D:$D, "") -> 99.61 | K41: =E41*I41 -> 685.72 | L41: =K41*H41 -> 0 | M41: =K41-L41 -> 685.72 | N41: =M41-(E41*J41) -> 287.28 | O41: =TEXT(B41,"mmm") -> 09/14/23
A42: ORD-50041 | B42: 45314 | C42: CUST-1526 | D42: P-2009 | E42: 4 | F42: =IF(E42<0,0,E42) -> 4 | G42: Online | H42: 0.15 | I42: =_xlfn.XLOOKUP(D42, 'retail_products'!$A:$A, 'retail_products'!$E:$E, "") -> 137.67 | J42: =_xlfn.XLOOKUP(D42, 'retail_products'!$A:$A, 'retail_products'!$D:$D, "") -> 65.4 | K42: =E42*I42 -> 550.68 | L42: =K42*H42 -> 82.602 | M42: =K42-L42 -> 468.078 | N42: =M42-(E42*J42) -> 206.478 | O42: =TEXT(B42,"mmm") -> Jan
A43: ORD-50042 | B43: 45110 | C43: CUST-1041 | D43: P-2015 | E43: 4 | F43: =IF(E43<0,0,E43) -> 4 | G43: Mobile App | H43: 0 | I43: =_xlfn.XLOOKUP(D43, 'retail_products'!$A:$A, 'retail_products'!$E:$E, "") -> 37.4 | J43: =_xlfn.XLOOKUP(D43, 'retail_products'!$A:$A, 'retail_products'!$D:$D, "") -> 16.06 | K43: =E43*I43 -> 149.6 | L43: =K43*H43 -> 0 | M43: =K43-L43 -> 149.6 | N43: =M43-(E43*J43) -> 85.36 | O43: =TEXT(B43,"mmm") -> Jul
A44: ORD-50043 | B44: 45332 | C44: CUST-1369 | D44: P-2025 | E44: 4 | F44: =IF(E44<0,0,E44) -> 4 | G44: Mobile App | H44: 0 | I44: =_xlfn.XLOOKUP(D44, 'retail_products'!$A:$A, 'retail_products'!$E:$E, "") -> 526.7 | J44: =_xlfn.XLOOKUP(D44, 'retail_products'!$A:$A, 'retail_products'!$D:$D, "") -> 234.96 | K44: =E44*I44 -> 2106.8 | L44: =K44*H44 -> 0 | M44: =K44-L44 -> 2106.8 | N44: =M44-(E44*J44) -> 1166.96 | O44: =TEXT(B44,"mmm") -> Feb
A45: ORD-50044 | B45: 45287 | C45: CUST-1991 | D45: P-2034 | E45: 3 | F45: =IF(E45<0,0,E45) -> 3 | G45: Online | H45: 0 | I45: =_xlfn.XLOOKUP(D45, 'retail_products'!$A:$A, 'retail_products'!$E:$E, "") -> 144.07 | J45: =_xlfn.XLOOKUP(D45, 'retail_products'!$A:$A, 'retail_products'!$D:$D, "") -> 65.87 | K45: =E45*I45 -> 432.21 | L45: =K45*H45 -> 0 | M45: =K45-L45 -> 432.21 | N45: =M45-(E45*J45) -> 234.6 | O45: =TEXT(B45,"mmm") -> Dec
...

Sheet Pivot Tables
A3: Total profit | E3: Total Revenue | I3: Total Orders | M3: Total Customers
A4: 1454389.3 | E4: 3601889.4 | I4: 2449 | M4: 931
N23: Row Labels | O23: Sum of profit
N24: Jan | O24: 206855.85
A25: Channels | B25: Total profit | N25: Feb | O25: 193123.92
A26: In-Store | B26: 472289.14 | N26: Mar | O26: 171580.77
A27: Mobile App | B27: 491236.37 | N27: Apr | O27: 89302.071
A28: Online | B28: 490863.8 | N28: May | O28: 98912.954
A29: Grand Total | B29: 1454389.3 | N29: Jun | O29: 102912.47
N30: Jul | O30: 98011.647
N31: Aug | O31: 85408.342
N32: Sep | O32: 95790.452
N33: Oct | O33: 93566.674
N34: Nov | O34: 104450.85
A35: Row Labels | B35: Sum of gross_revenue | H35: Row Labels | I35: Sum of gross_revenue | N35: Dec | O35: 114473.32
A36: In-Store | B36: 1178386.1 | H36: Jan | I36: 514309.74 | N36: Grand Total | O36: 1454389.3
A37: Mobile App | B37: 1223718.7 | H37: Feb | I37: 483593.76
A38: Online | B38: 1199784.7 | H38: Mar | I38: 442578.08
A39: Grand Total | B39: 3601889.4 | H39: Apr | I39: 220418.29
H40: May | I40: 239377.38
H41: Jun | I41: 251572.15
H42: Jul | I42: 241180.53
H43: Aug | I43: 213989.4
B44: Row Labels | C44: Sum of profit | H44: Sep | I44: 235579.08
B45: Jan | C45: 206855.85 | H45: Oct | I45: 228693.35
B46: Feb | C46: 193123.92 | H46: Nov | I46: 251098.73
B47: Mar | C47: 171580.77 | H47: Dec | I47: 279498.91
B48: Apr | C48: 89302.071 | H48: Grand Total | I48: 3601889.4
B49: May | C49: 98912.954
B50: Jun | C50: 102912.47
B51: Jul | C51: 98011.647
B52: Aug | C52: 85408.342
B53: Sep | C53: 95790.452
B54: Oct | C54: 93566.674
B55: Nov | C55: 104450.85
B56: Dec | C56: 114473.32
B57: Grand Total | C57: 1454389.3

Sheet Dashboard
A1: Retail Sales Performance Dashboard
A28: Dashboard created by Victor Weka Excel • Power Pivot • Pivot Tables

Sheet month
A1: month_no | B1: month
A2: 1 | B2: Jan
A3: 2 | B3: Feb
A4: 3 | B4: Mar
A5: 4 | B5: Apr
A6: 5 | B6: May
A7: 6 | B7: Jun
A8: 7 | B8: Jul
A9: 8 | B9: Aug
A10: 9 | B10: Sep
A11: 10 | B11: Oct
A12: 11 | B12: Nov
A13: 12 | B13: Dec
